Workbook

Sheet FICHA DE SERVICIO
B4: 1 FICHA DE ESPECIFICACIÓN DE SERVICIO
B6: 1. DATOS GENERALES
C7: Nombre del servicio: | D7: Uñas Acrílicas Baby Boomer
C8: Código: | D8: 0004
C9: Responsable: | D9: Génesis Balla
C10: Fecha de elaboración: | D10: 5 de mayo
B11: 2. DESCRIPCIÓN DEL SERVICIO
C12: Detalle del servicio: | D12: Aplicación de uñas acrílicas con efecto Baby Boomer, caracterizado por un degradado suave entre tonos nude y blanco, proporcionando una apariencia elegante, natural y moderna
B15: 3. REQUISITOS DEL CLIENTE
C16: Resultado esperado: | D16: Apariencia natural, elegante y uniforme con acabado brillante.
C17: Tiempo máximo aceptable: | D17: 2 horas
C18: Preferencias: | D18: Tonos suaves, diseño delicado, largo y forma según la elección del cliente.
C19: Condiciones previas del cliente: | D19: Uñas naturales limpias Sin infecciones ni heridas en manos o uñas Retiro previo de esmalte o acrílico anterior (si aplica)
B20: 4. INSUMOS Y HERRAMIENTAS
C21: Insumo 1: | D21: Acrílico nude Acrílico blanco Monómero Primer y deshidratador Tips o moldes Pegamento para tips Top coat brillante Aceite de cutícula
C22: Insumo 2: | D22: Pinceles para acrílico Limas y buffer Corta tips Torno eléctrico (opcional) Lámpara UV/LED Empujador de cutícula Cepillo limpiador
C23: Insumo 3: | D23: Alcohol o desinfectante Guantes Toallas desechables Esterilizador de herramientas
B25: 5. PROCEDIMIENTO ESTÁNDAR
C26: Paso 1: | D26: Desinfectar manos y herramientas. Retirar residuos o esmalte anterior. Preparar la uña natural retirando brillo y cutícula.
C27: Paso 2: | D27: Colocar tips o moldes según el largo deseado. Aplicar primer y acrílico nude como base
C28: Paso 3: | D28: Aplicar acrílico blanco en la punta. Difuminar cuidadosamente para lograr el efecto degradado
C29: Paso 4: | D29: Dar forma y grosor uniforme a todas las uñas. Corregir imperfecciones con lima o torno. Aplicar top coat brillante. Curar en lámpara UV/LED. Aplicar aceite de cutícula.
B31: 6. TIEMPO ESTÁNDAR
C32: Duración mínima: | D32: 1 hora 30 minutos
C33: Duración máxima: | D33: 2 horas
B35: 7. CRITERIOS DE CALIDAD
C36: Acabado: | D36: Degradado suave, limpio y brillante.
C37: Uniformidad: | D37: Igual intensidad de color, tamaño y forma en todas las uñas.
C38: Resistencia | D38: Acrílico correctamente adherido y sin levantamientos
C39: Higiene: | D39: Área limpia, herramientas esterilizadas y correcta desinfección
C40: Comodidad del cliente: | D40: Proceso realizado sin causar molestias o dolor.
B41: Higiene:
C42: Área y herramientas limpias y esterilizadas
B43: 8. TOLERANCIAS
B44: Descripción:
B45: Variación mínima en el degradado debido al trabajo manual. Diferencia leve en tonalidad según iluminación. Margen máximo de diferencia de longitud: 1 mm entre uñas
B46: 9. CRITERIOS DE ACEPTACIÓN
B47: ✔ Cliente satisfecho
B48: ✔ Inspección visual conforme
B49: ✓degradado uniforme
...

Sheet Checklist_Control_Interno
B3: 1 CHECKLIST DE CONTROL INTERNO DE SERVICIO
B5: Servicio: Uñas Acrílicas Baby Boomer
B6: Fecha: 5 de mayo
B7: Responsable: Genesis Balla
B9: CRITERIO | C9: Cumple (si/no) | D9: Calificacion 1 a 5 | E9: Observaciones
B10: Área limpia antes de iniciar | C10: si | D10: 5 | E10: Área completamente desinfectada
B11: Herramientas esterilizadas | C11: si | D11: 5 | E11: Herramientas en buen estado
B12: Diagnóstico realizado | C12: si | D12: 4 | E12: Faltó preguntar sobre sensibilidad
B13: Uso correcto de productos | C13: si | D13: 5 | E13: Buena aplicación del acrílico
B14: Cumplimiento del procedimiento | C14: si | D14: 5 | E14: Procedimiento correcto
B15: Tiempo dentro del estándar | C15: no | D15: 3 | E15: Se tardó 10 minutos más
B16: Resultado uniforme | C16: si | D16: 4 | E16: Leve diferencia en el degradado
B17: Cliente satisfecho | C17: si | D17: 5 | E17: Cliente conforme
B19: TOTAL : | C19: =D19/40 -> 0.9 | D19: =SUM(D10:D17) -> 36
B20: OBSERVACIONES: Se recomienda mejorar la técnica de difuminado para mayor uniformidad.
B25: 2 CHECKLIST DE CONTROL INTERNO DE SERVICIO
B27: Servicio: Uñas Acrílicas Baby Boomer
B28: Fecha: 6 de mayo
B29: Responsable: Génesis Balla
B31: CRITERIO | C31: Cumple (si/no) | D31: Calificacion 1 a 5 | E31: Observaciones
B32: Área limpia antes de iniciar | C32: si | D32: 5 | E32: Espacio ordenado
B33: Herramientas esterilizadas | C33: si | D33: 5 | E33: Esterilización adecuada
B34: Diagnóstico realizado | C34: si | D34: 5 | E34: Cliente asesorada correctamente
B35: Uso correcto de productos | C35: si | D35: 4 | E35: Exceso minimo de producto
B36: Cumplimiento del procedimiento | C36: si | D36: 4 | E36: Retraso en sellado final
B37: Tiempo dentro del estándar | C37: si | D37: 5 | E37: Se terminó el servicio 10 minutos antes del tiempo máximo
B38: Resultado uniforme | C38: si | D38: 5 | E38: Excelente degradado
B39: Cliente satisfecho | C39: si | D39: 5 | E39: cliente satisfecho
B41: TOTAL : | C41: =D41/40 -> 0.95 | D41: =D32+D33+D34+D35+D36+D37+D38+D39 -> 38
B42: OBSERVACIONES: | C42: Mejorar la cantidad de producto utilizado para evitar exceso de grosor.
B47: 3 CHECKLIST DE CONTROL INTERNO DE SERVICIO
B49: Servicio: uñas baby boomer
B50: Fecha: 7 mayo
B51: Responsable: Génesis Balla
B53: CRITERIO | C53: Cumple (si/no) | D53: Calificacion 1 a 5 | E53: Observaciones
B54: Área limpia antes de iniciar | C54: si | D54: 4 | E54: Área limpia pero poco organizada
B55: Herramientas esterilizadas | C55: si | D55: 5 | E55: Material correctamente esterilizado
B56: Diagnóstico realizado | C56: si | D56: 4 | E56: Diagnóstico rápido
B57: Uso correcto de productos | C57: si | D57: 5 | E57: Aplicación correcta
B58: Cumplimiento del procedimiento | C58: si | D58: 4 | E58: Difuminado tomó más tiempo
...

Sheet Checklist_Cliente
B3: 1 CHECKLIST DE CALIFICACIÓN AL SERVICIO
B5: Servicio: Uñas Acrílicas Baby Boomer
B6: Fecha: 5 de mayo
B7: Responsable: Genesis Balla
B8: Cliente: Abigail Andrade
B10: CRITERIO | C10: Calificacion 1= Muy deficiente 2= Deficiente 3= Regular 4= Bueno 5= Excelente | D10: Observaciones
B11: Atención y amabilidad del personal. | C11: 5 | D11: Ninguna
B12: Limpieza e higiene del lugar. | C12: 5 | D12: Ninguna
B13: Puntualidad en el inicio del servicio. | C13: 4 | D13: Demoró unos pocos minutos
B14: Explicación clara del procedimiento. | C14: 5 | D14: Ninguna
B15: Cumplimiento de lo solicitado. | C15: 4 | D15: Cumple con lo que se pide
B16: Criterios de calidad del acabado final: Color, degradado, simetría y forma de las uñas, comodidad durante el servicio, resistencia del acrílico. | C16: 4 | D16: Un poco de diferencia en el degradado con el de la imagen y una uña no tan recta
B17: Duración aparente del servicio. | C17: 4 | D17: Se demoró unos minutos más del tiempo máximo
B18: Satisfacción general. | C18: 4 | D18: Me agradó el resultado
B19: Probabilidad de volver a atenderse. | C19: 5 | D19: Por la buena atención
B20: Probabilidad de recomendar el servicio. | C20: 5 | D20: Realiza un bonito trabajo
B21: PROMEDIO DE CALIFICACIÓN: | C21: =SUM(C11:C20)/10 -> 4.5
B26: 2 CHECKLIST DE CALIFICACIÓN AL SERVICIO
B28: Servicio: Uñas Acrílicas Baby Boomer
B29: Fecha: 6 de mayo
B30: Responsable: Génesis Balla
B31: Cliente: María Ube
B33: CRITERIO | C33: Calificacion 1= Muy deficiente 2= Deficiente 3= Regular 4= Bueno 5= Excelente | D33: Observaciones
B34: Atención y amabilidad del personal. | C34: 5 | D34: Sin observaciones
B35: Limpieza e higiene del lugar. | C35: 5 | D35: Sin observaciones
B36: Puntualidad en el inicio del servicio. | C36: 5 | D36: Sin observaciones
B37: Explicación clara del procedimiento. | C37: 5 | D37: Sin observaciones
B38: Cumplimiento de lo solicitado. | C38: 5 | D38: Sin observaciones
B39: Criterios de calidad del acabado final: Color, degradado, simetría y forma de las uñas, comodidad durante el servicio, resistencia del acrílico. | C39: 5 | D39: Sin observaciones
B40: Duración aparente del servicio. | C40: 5 | D40: Sin observaciones
B41: Satisfacción general. | C41: 5 | D41: Sin observaciones
B42: Probabilidad de volver a atenderse. | C42: 5 | D42: Sin observaciones
B43: Probabilidad de recomendar el servicio. | C43: 5 | D43: Sin observaciones
B44: PROMEDIO DE CALIFICACIÓN: | C44: =SUM(C34:C43)/10 -> 5
B49: 3 CHECKLIST DE CALIFICACIÓN AL SERVICIO
B51: Servicio: Uñas baby boomer
B52: Fecha: 7 mayo
B53: Responsable: Génesis Balla
B54: Cliente: Elena Villacis
B56: CRITERIO | C56: Calificacion 1= Muy deficiente 2= Deficiente 3= Regular 4= Bueno 5= Excelente | D56: Observaciones
...

Sheet MAPA DE PROCESOS 
A3: Etapas del proceso | B3: Actividades | C3: Que se evalúa
A4: Reserva de la cita | B4: • Contacto con el cliente • Información del servicio al cliente • Verificación de espacio (tiempo) • Confirmación de agenda de la cita | C4: Tiempo de cierre de la cita
A5: Recepción del cliente | B5: • Recepción y saludo al cliente. • Verificación de la cita y diseño solicitado. | C5: Tiempo de espera del cliente para der atendida
A6: Preparación del servicio | B6: • Lavado y desinfección de manos del profesional • Desinfección del área de trabajo. • Esterilización y organización de herramientas. • Preparación de materiales e insumos antes de iniciar el servicio. | C6: Cumplimiento de higiene y organización
A7: Preparación de la clienta | B7: • Lavado y desinfección de manos de la cliente. • Revisión del estado de las uñas y manos del cliente. • Identificación de heridas, alergias o infecciones. • Retiro de esmalte o acrílico anterior si aplica. • Retiro de brillo natural de la uña. • Empuje y limpieza de cutícula. • Selección del tamaño correcto de tips o moldes. | C7: Cumplimiento del protocolo
A8: Aplicación de estructura acrílica | B8: • Colocación y fijación correcta de tips o moldes. • Corte de tips según largo solicitado. • Aplicación de primer y deshidratador. • Preparación adecuada de mezcla acrílica. • Aplicación de acrílico nude como base principal. • Distribución uniforme del producto. • Control del grosor de la uña. • Aplicación de acrílico blanco en la punta. • Difuminado del color blanco para lograr el efecto Baby Boomer. • Corrección inmediata de imperfecciones durante la aplicación. • Verificación de simetría y estructura en cada uña | C8: Técnica de aplicación, uniformidad, uso correcto de producto, precisión del degradado, estructura y grosor adecuado
A9: Acabado y perfeccionamiento | B9: • Limado de superficie y laterales. • Definición de forma final de las uñas. • Corrección de desniveles o exceso de producto. • Pulido de superficie para acabado uniforme. • Eliminación de residuos de limado. • Aplicación de top coat brillante. • Curado en lámpara UV/LED. • Aplicación de aceite para cutícula. • Limpieza final de manos y uñas. • Revisión visual del acabado final. | C9: Calidad del acabado final: Brillo, uniformidad, forma, limpieza, resistencia, acabado profesional y tiempo del servicio.
A10: Evaluación final del servicio y recomendaciones | B10: • Verificación del resultado final junto al cliente. • Comparación del diseño realizado con el solicitado. • Confirmación de uniformidad y brillo. • Revisión de levantamientos, burbujas o imperfecciones. • Consulta de comodidad y satisfacción del cliente. • Entrega de recomendaciones de cuidado y mantenimiento • Cobro del servicio • Registro de observaciones del cliente. • Aplicación del checklist de evaluación al cliente. • Confirmación del tiempo total del servicio. • Cierre y despedida del cliente | C10: Nivel de Satisfacción del cliente: Calidad visual, cumplimiento de estándares, aceptación del servicio y experiencia del cliente.
A11: Seguimiento Post - Servicio | B11: • Contacto con el cliente después de 7 días • Preguntar en que estado está el trabajo realizado • Recordamiento de cuidado • Encuesta de satisfacción | C11: Satisfacción del cliente, Calificación la calidad del servicio.
D15: PROCESO OPERATIVO CLIENTES | F15: PROCESO ESTRATÉGICO | V15: CLIENTES SATISFECHOS
F16: PLANIFICACIÓN ESTRATÉGICA | I16: GESTIÓN ADMINISTRATIVA | M16: DISEÑO DE SERVICIOS | Q16: CONTABILIDAD | T16: GESTIÓN DE LA CALIDAD
F19: RESERVA DE LA CITA | H19: RECEPCIÓN DEL CLIENTE | J19: PREPARACIÓN DEL SERVICIO | L19: PREPARACIÓN DE LA CLIENTA | N19: APLICACIÓN DE ESTRUCTURA ACRÍLICA | P19: ACABADO Y PERFECCIONAMIENTO | R19: EVALUACIÓN FINAL DEL SERVICIO Y RECOMENDACIONES | T19: SEGUIMIENTO POST SERVICIO
F23: PROCESOS DE APOYO
F24: PROCESO DE COMPRAS | M24: LIMPIEZA Y BIOSEGURIDAD | S24: MARKETING Y REDES SOCIALES

Sheet TABLA DE DATOS
A1: ID | B1: Fecha | C1: Cliente | D1: Manicurista | E1: Servicio | F1: Nivel de satisfacción del cliente (de 1 a 5) 1: Muy Insatisfecho 2: Insatisfecho 3: Neutral 4: Satisfecho 5: Muy satisfecho | G1: Tiempo Demorado en el servicio (minutos) | H1: Cumplimiento del protoco | I1: Calidad del acabado final
A2: 000-4 | B2: 46147 | C2: Abigail Andrade | D2: Génesis Balla | E2: Uñas acrílicas baby boomer | F2: =Checklist_Cliente!C21 -> 4.5 | G2: 130 | H2: =Checklist_Control_Interno!C19 -> 0.9 | I2: 4
A3: 000-4 | B3: 46148 | C3: María Ube | D3: Génesis Balla | E3: Uñas acrílicas baby boomer | F3: =Checklist_Cliente!C44 -> 5 | G3: 110 | H3: =Checklist_Control_Interno!C41 -> 0.95 | I3: 5
A4: 000-4 | B4: 46149 | C4: Elena Villacis | D4: Génesis Balla | E4: Uñas acrílicas baby boomer | F4: =Checklist_Cliente!C67 -> 4 | G4: 140 | H4: =Checklist_Control_Interno!C63 -> 0.8 | I4: 4
A5: 000-4 | B5: 46150 | C5: Alexa Macías | D5: Génesis Balla | E5: Uñas acrílicas baby boomer | F5: =Checklist_Cliente!C90 -> 5 | G5: 105 | H5: =Checklist_Control_Interno!C85 -> 1 | I5: 5
A6: 000-4 | B6: 46151 | C6: Verónica Hermida | D6: Génesis Balla | E6: Uñas acrílicas baby boomer | F6: =Checklist_Cliente!C113 -> 4.2 | G6: 125 | H6: =Checklist_Control_Interno!C107 -> 0.85 | I6: 3
A7: 000-4 | B7: 46153 | C7: Elizabeth Sánchez | D7: Génesis Balla | E7: Uñas acrílicas baby boomer | F7: =Checklist_Cliente!C136 -> 3.2 | G7: 130 | H7: =Checklist_Control_Interno!C129 -> 0.875 | I7: 3
A8: 000-4 | B8: 46153 | C8: Leonor Gómez | D8: Génesis Balla | E8: Uñas acrílicas baby boomer | F8: =Checklist_Cliente!C159 -> 4.1 | G8: 120 | H8: =Checklist_Control_Interno!C151 -> 0.9 | I8: 4
A9: 000-4 | B9: 46153 | C9: Natasha Morán | D9: Génesis Balla | E9: Uñas acrílicas baby boomer | F9: =Checklist_Cliente!C182 -> 4 | G9: 140 | H9: =Checklist_Control_Interno!C173 -> 0.7 | I9: 4
A10: 000-4 | B10: 46154 | C10: Cinthya Alvarado | D10: Génesis Balla | E10: Uñas acrílicas baby boomer | F10: =Checklist_Cliente!C205 -> 5 | G10: 110 | H10: =Checklist_Control_Interno!C195 -> 1 | I10: 5
A11: 000-4 | B11: 46155 | C11: Cristina Alvarado | D11: Génesis Balla | E11: Uñas acrílicas baby boomer | F11: =Checklist_Cliente!C228 -> 4.9 | G11: 115 | H11: =Checklist_Control_Interno!C217 -> 0.925 | I11: 5
A12: 000-4 | B12: 46155 | C12: Lucía Maldonado | D12: Génesis Balla | E12: Uñas acrílicas baby boomer | F12: =Checklist_Cliente!C251 -> 4.8 | G12: 120 | H12: =Checklist_Control_Interno!C217 -> 0.925 | I12: 5
A13: 000-4 | B13: 46156 | C13: Linda Pluas | D13: Génesis Balla | E13: Uñas acrílicas baby boomer | F13: =Checklist_Cliente!C274 -> 4.5 | G13: 120 | H13: =Checklist_Control_Interno!C239 -> 0.85 | I13: 4
A14: 000-4 | B14: 46156 | C14: Estefania Bonozo | D14: Génesis Balla | E14: Uñas acrílicas baby boomer | F14: =Checklist_Cliente!C297 -> 3.7 | G14: 135 | H14: =Checklist_Control_Interno!C283 -> 0.85 | I14: 4
A15: 000-4 | B15: 46157 | C15: Iris Gutierrez | D15: Génesis Balla | E15: Uñas acrílicas baby boomer | F15: =Checklist_Cliente!C320 -> 4.5 | G15: 125 | H15: =Checklist_Control_Interno!C305 -> 0.825 | I15: 4
A16: 000-4 | B16: 46157 | C16: Melanie Rugel | D16: Génesis Balla | E16: Uñas acrílicas baby boomer | F16: =Checklist_Cliente!C343 -> 5 | G16: 125 | H16: =Checklist_Control_Interno!C327 -> 0.9 | I16: 5
A17: 000-4 | B17: 46158 | C17: Monica Lasso | D17: Génesis Balla | E17: Uñas acrílicas baby boomer | F17: =Checklist_Cliente!C366 -> 4.3 | G17: 135 | H17: =Checklist_Control_Interno!C349 -> 0.825 | I17: 5
A18: 000-4 | B18: 46158 | C18: Mariela Jiménez | D18: Génesis Balla | E18: Uñas acrílicas baby boomer | F18: =Checklist_Cliente!C389 -> 4.7 | G18: 130 | H18: =Checklist_Control_Interno!C371 -> 0.9 | I18: 4
A19: 000-4 | B19: 46159 | C19: Alexa Conforme | D19: Génesis Balla | E19: Uñas acrílicas baby boomer | F19: =Checklist_Cliente!C412 -> 5 | G19: 120 | H19: =Checklist_Control_Interno!C393 -> 0.975 | I19: 5
A20: 000-4 | B20: 46159 | C20: Amelia Carrasco | D20: Génesis Balla | E20: Uñas acrílicas baby boomer | F20: =Checklist_Cliente!C435 -> 4.7 | G20: 120 | H20: =Checklist_Control_Interno!C415 -> 0.875 | I20: 4
A21: 000-4 | B21: 46160 | C21: Arianna | D21: Génesis Balla | E21: Uñas acrílicas baby boomer | F21: =Checklist_Cliente!C458 -> 3.9 | G21: 130 | H21: =Checklist_Control_Interno!C437 -> 0.875 | I21: 4
